Workbook

Sheet Cover
A1: Chipotle Mexican Grill (NYSE: CMG)
A2: Three-Statement Financial Model & DCF Valuation
A4: Built by Heer Patel
A5: heerpatel7016@gmail.com
A7: Model Overview
A8: Five years of historical financials (2021A - 2025A) sourced from 10-K filings on SEC EDGAR, with a five year forward forecast (2026E - 2030E) integrated across Income Statement, Balance Sheet, and Cash Flow Statement. DCF valuation includes terminal value, WACC build, and Bull / Base / Bear scenario analysis with dynamic toggle.
A10: Key Findings
A11: Base case implied share price: $19.43 vs. $32.89 current (40.9%)
A12: Bull case implied price: $29.80 (9.4%)
A13: Bear case implied price: $13.10 (60.2%)
A14: Conclusion: CMG is fully valued to overvalued at current levels across all three scenarios.
A16: Tab Guide
... A28: Chipotle Mexican Grill 10-K filings (2021 - 2025), SEC EDGAR

Sheet Assumptions
A1: Chipotle Mexican Grill - Forecast Assumptions
A2: Drivers for fiscal years 2026E - 2030E
A4: Driver | B4: 2021A | C4: 2022A | D4: 2023A | E4: 2024A | F4: 2025A | G4: 2026E | H4: 2027E | I4: 2028E | J4: 2029E | K4: 2030E | M4: Scenarios: | N4: Base
A6: Revenue Drivers
A7: Total restaurants - beginning of year | B7: 2768 | C7: 2966 | D7: 3187 | E7: 3437 | F7: 3726 | G7: =F10 -> 4042 | H7: =G10 -> 4342 | I7: =H10 -> 4657 | J7: =I10 -> 4987 | K7: =J10 -> 5332
A8: Gross new openings | B8: 215 | C8: 235 | D8: 270 | E8: 304 | F8: 334 | G8: =IF($N$4="Bear",C51,IF($N$4="Base",D51,E51)) -> 320 | H8: =IF($N$4="Bear",C52,IF($N$4="Base",D52,E52)) -> 335 | I8: =IF($N$4="Bear",C53,IF($N$4="Base",D53,E53)) -> 350 | J8: =IF($N$4="Bear",C54,IF($N$4="Base",D54,E54)) -> 365 | K8: =IF($N$4="Bear",C55,IF($N$4="Base",D55,E55)) -> 380
A9: Closures and relocation | B9: -17 | C9: -15 | D9: -15 | E9: -15 | F9: -18 | G9: -20 | H9: -20 | I9: -20 | J9: -20 | K9: -20
A10: Total restaurants - end of year | B10: =sum(B7:B9) -> 2966 | C10: =sum(C7:C9) -> 3186 | D10: =sum(D7:D9) -> 3442 | E10: =sum(E7:E9) -> 3726 | F10: =sum(F7:F9) -> 4042 | G10: =sum(G7:G9) -> 4342 | H10: =sum(H7:H9) -> 4657 | I10: =sum(I7:I9) -> 4987 | ... K10: =sum(K7:K9) -> 5692
A11: Average restaurant count | B11: =(B7+B10)/2 -> 2867 | C11: =(C7+C10)/2 -> 3076 | D11: =(D7+D10)/2 -> 3314.5 | E11: =(E7+E10)/2 -> 3581.5 | F11: =(F7+F10)/2 -> 3884 | G11: =(G7+G10)/2 -> 4192 | H11: =(H7+H10)/2 -> 4499.5 | I11: =(I7+I10)/2 -> 4822 | ... K11: =(K7+K10)/2 -> 5512
A12: Average unit volume (AUV) | B12: ='Income Statement'!B6/B11 -> 2632.3896 | C12: ='Income Statement'!C6/C11 -> 2807.104 | D12: ='Income Statement'!D6/D11 -> 2978.3222 | E12: ='Income Statement'!E6/E11 -> 3158.9705 | F12: ='Income Statement'!F6/F11 -> 3070.4431 | G12: =F12*(1+G13) -> 3131.852 | H12: =G12*(1+H13) -> 3210.1483 | I12: =H12*(1+I13) -> 3290.402 | J12: =I12*(1+J13) -> 3372.662 | K12: =J12*(1+K13) -> 3440.1153
A13: AUV growth % | C13: =C12/B12-1 -> 0.066371036 | D13: =D12/C12-1 -> 0.060994601 | E13: =E12/D12-1 -> 0.060654392 | F13: =F12/E12-1 -> -0.028024143 | G13: =IF($N$4="Bear",C56,IF($N$4="Base",D56,E56)) -> 0.02 | H13: =IF($N$4="Bear",C57,IF($N$4="Base",D57,E57)) -> 0.025 | I13: =IF($N$4="Bear",C58,IF($N$4="Base",D58,E58)) -> 0.025 | J13: =IF($N$4="Bear",C59,IF($N$4="Base",D59,E59)) -> 0.025 | K13: =IF($N$4="Bear",C60,IF($N$4="Base",D60,E60)) -> 0.02
A14: Implied revenue | B14: =B11*B12 -> 7547061 | C14: =C11*C12 -> 8634652 | D14: =D11*D12 -> 9871649 | E14: =E11*E12 -> 11313853 | F14: =F11*F12 -> 11925601 | G14: =G11*G12 -> 13128723 | H14: =H11*H12 -> 14444062 | I14: =I11*I12 -> 15866318 | ... K14: =K11*K12 -> 18961915
A15: Revenue growth % | C15: =C14/B14-1 -> 0.14410789 | D15: =D14/C14-1 -> 0.14325962 | E15: =E14/D14-1 -> 0.14609555 | F15: =F14/E14-1 -> 0.054070704 | G15: =G14/F14-1 -> 0.10088568 | H15: =H14/G14-1 -> 0.10018786 | I15: =I14/H14-1 -> 0.098466496 | J15: =J14/I14-1 -> 0.096741497 | K15: =K14/J14-1 -> 0.089686985
A17: Cost Structure (% of Revenue)
A18: Food, beverage and packaging % | B18: ='Income Statement'!B7/'Income Statement'!B6 -> 0.30589802 | C18: ='Income Statement'!C7/'Income Statement'!C6 -> 0.30137231 | D18: ='Income Statement'!D7/'Income Statement'!D6 -> 0.29504331 | E18: ='Income Statement'!E7/'Income Statement'!E6 -> 0.29826408 | F18: ='Income Statement'!F7/'Income Statement'!F6 -> 0.29574962 | G18: =IF($N$4="Bear",$C$61,IF($N$4="Base",$D$61,$E$61)) -> 0.295 | H18: =IF($N$4="Bear",$C$61,IF($N$4="Base",$D$61,$E$61)) -> 0.295 | I18: =IF($N$4="Bear",$C$61,IF($N$4="Base",$D$61,$E$61)) -> 0.295 | J18: =IF($N$4="Bear",$C$61,IF($N$4="Base",$D$61,$E$61)) -> 0.295 | K18: =IF($N$4="Bear",$C$61,IF($N$4="Base",$D$61,$E$61)) -> 0.295
A19: Labor % | B19: ='Income Statement'!B8/'Income Statement'!B6 -> 0.254107 | C19: ='Income Statement'!C8/'Income Statement'!C6 -> 0.25455085 | D19: ='Income Statement'!D8/'Income Statement'!D6 -> 0.24727196 | E19: ='Income Statement'!E8/'Income Statement'!E6 -> 0.24658169 | F19: ='Income Statement'!F8/'Income Statement'!F6 -> 0.25086199 | G19: =IF($N$4="Bear",$C$62,IF($N$4="Base",$D$62,$E$62)) -> 0.25 | H19: =IF($N$4="Bear",$C$62,IF($N$4="Base",$D$62,$E$62)) -> 0.25 | I19: =IF($N$4="Bear",$C$62,IF($N$4="Base",$D$62,$E$62)) -> 0.25 | J19: =IF($N$4="Bear",$C$62,IF($N$4="Base",$D$62,$E$62)) -> 0.25 | K19: =IF($N$4="Bear",$C$62,IF($N$4="Base",$D$62,$E$62)) -> 0.25
A20: Occupancy % | B20: ='Income Statement'!B9/'Income Statement'!B6 -> 0.055201091 | C20: ='Income Statement'!C9/'Income Statement'!C6 -> 0.053322936 | D20: ='Income Statement'!D9/'Income Statement'!D6 -> 0.050980743 | E20: ='Income Statement'!E9/'Income Statement'!E6 -> 0.049795061 | F20: ='Income Statement'!F9/'Income Statement'!F6 -> 0.052399707 | G20: 0.051 | H20: 0.051 | I20: 0.051 | J20: 0.05 | K20: 0.05
A21: Other operating cost % | B21: ='Income Statement'!B10/'Income Statement'!B6 -> 0.15861194 | C21: ='Income Statement'!C10/'Income Statement'!C6 -> 0.1519349 | D21: ='Income Statement'!D10/'Income Statement'!D6 -> 0.14473235 | E21: ='Income Statement'!E10/'Income Statement'!E6 -> 0.13863376 | F21: ='Income Statement'!F10/'Income Statement'!F6 -> 0.14723149 | G21: 0.145 | H21: 0.145 | I21: 0.145 | J21: 0.145 | K21: 0.145
A22: General and administrative % | B22: ='Income Statement'!B11/'Income Statement'!B6 -> 0.080409314 | C22: ='Income Statement'!C11/'Income Statement'!C6 -> 0.065340329 | D22: ='Income Statement'!D11/'Income Statement'!D6 -> 0.064182185 | E22: ='Income Statement'!E11/'Income Statement'!E6 -> 0.061648582 | F22: ='Income Statement'!F11/'Income Statement'!F6 -> 0.054673723 | G22: =IF($N$4="Bear",$C$63,IF($N$4="Base",$D$63,$E$63)) -> 0.055 | H22: =IF($N$4="Bear",$C$63,IF($N$4="Base",$D$63,$E$63)) -> 0.055 | I22: =IF($N$4="Bear",$C$63,IF($N$4="Base",$D$63,$E$63)) -> 0.055 | J22: =IF($N$4="Bear",$C$63,IF($N$4="Base",$D$63,$E$63)) -> 0.055 | K22: =IF($N$4="Bear",$C$63,IF($N$4="Base",$D$63,$E$63)) -> 0.055
A23: Depriciation and amortization % | B23: ='Income Statement'!B12/'Income Statement'!B6 -> 0.033742539 | C23: ='Income Statement'!C12/'Income Statement'!C6 -> 0.033218015 | D23: ='Income Statement'!D12/'Income Statement'!D6 -> 0.032354675 | E23: ='Income Statement'!E12/'Income Statement'!E6 -> 0.02961237 | F23: ='Income Statement'!F12/'Income Statement'!F6 -> 0.030303043 | G23: 0.03 | H23: 0.03 | I23: 0.03 | J23: 0.03 | K23: 0.03
A24: Pre-opening cost per new store ($k) | B24: ='Income Statement'!B13/B8 -> 98.902326 | C24: ='Income Statement'!C13/C8 -> 125.78723 | D24: ='Income Statement'!D13/D8 -> 136.78148 | E24: ='Income Statement'!E13/E8 -> 137.81908 | F24: ='Income Statement'!F13/F8 -> 148.22455 | G24: 160 | H24: 160 | I24: 160 | J24: 160 | K24: 160
A25: Impairment/closure | B25: ='Income Statement'!B14 -> 19291 | C25: ='Income Statement'!C14 -> 21139 | D25: ='Income Statement'!D14 -> 38370 | E25: ='Income Statement'!E14 -> 26949 | F25: ='Income Statement'!F14 -> 27503 | G25: 30000 | H25: 30000 | I25: 30000 | J25: 30000 | K25: 30000
A27: Working Capital (Days)
A28: Days sales outstanding (DSO) | B28: ='Balance Sheet'!B8/'Income Statement'!B6*365 -> 4.8169261 | C28: ='Balance Sheet'!C8/'Income Statement'!C6*365 -> 4.5179817 | D28: ='Balance Sheet'!D8/'Income Statement'!D6*365 -> 4.2718572 | E28: ='Balance Sheet'!E8/'Income Statement'!E6*365 -> 4.6444385 | F28: ='Balance Sheet'!F8/'Income Statement'!F6*365 -> 4.7888647 | G28: 5 | H28: 5 | I28: 5 | J28: 5 | K28: 5
A29: Days inventory outstanding (DIO) | B29: ='Balance Sheet'!B9/'Income Statement'!B7*365 -> 5.1898679 | C29: ='Balance Sheet'!C9/'Income Statement'!C7*365 -> 5.0029186 | D29: ='Balance Sheet'!D9/'Income Statement'!D7*365 -> 4.9261699 | E29: ='Balance Sheet'!E9/'Income Statement'!E7*365 -> 5.2937458 | F29: ='Balance Sheet'!F9/'Income Statement'!F7*365 -> 5.123465 | G29: 5 | H29: 5 | I29: 5 | J29: 5 | K29: 5
A30: Days payable outstanding (DPO) | B30: ='Balance Sheet'!B21/'Income Statement'!B7*365 -> 25.796138 | C30: ='Balance Sheet'!C21/'Income Statement'!C7*365 -> 25.887874 | D30: ='Balance Sheet'!D21/'Income Statement'!D7*365 -> 24.768826 | E30: ='Balance Sheet'!E21/'Income Statement'!E7*365 -> 22.789542 | F30: ='Balance Sheet'!F21/'Income Statement'!F7*365 -> 22.02351 | G30: 23 | H30: 23 | I30: 23 | J30: 23 | K30: 23
A31: Other current items as % of revenue | B31: =('Balance Sheet'!B10+'Balance Sheet'!B11)/'Income Statement'!B6 -> 0.02289898 | C31: =('Balance Sheet'!C10+'Balance Sheet'!C11)/'Income Statement'!C6 -> 0.015536584 | D31: =('Balance Sheet'!D10+'Balance Sheet'!D11)/'Income Statement'!D6 -> 0.017263782 | E31: =('Balance Sheet'!E10+'Balance Sheet'!E11)/'Income Statement'!E6 -> 0.014563297 | F31: =('Balance Sheet'!F10+'Balance Sheet'!F11)/'Income Statement'!F6 -> 0.017763717 | G31: 0.02 | H31: 0.02 | I31: 0.02 | J31: 0.02 | K31: 0.02
A33: Capital Expenditures
A34: CapEx per new restaurant ($K) | B34: =-'Cash Flow'!B28/B8 -> 2058.0233 | C34: =-'Cash Flow'!C28/C8 -> 2038.9957 | D34: =-'Cash Flow'!D28/D8 -> 2076.7815 | E34: =-'Cash Flow'!E28/E8 -> 1952.6414 | F34: =-'Cash Flow'!F28/F8 -> 1995.018 | G34: 1950 | H34: 1950 | I34: 1950 | J34: 1950 | K34: 1950
A35: Maintenance CapEx (% of revenue) | G35: 0.02 | H35: 0.02 | I35: 0.02 | J35: 0.02 | K35: 0.02
A36: total CapEx ($K) | B36: =-'Cash Flow'!B28 -> 442475 | C36: =-'Cash Flow'!C28 -> 479164 | D36: =-'Cash Flow'!D28 -> 560731 | E36: =-'Cash Flow'!E28 -> 593603 | F36: =-'Cash Flow'!F28 -> 666336 | G36: =G34*G8+G35*G14 -> 886574.47 | H36: =H34*H8+H35*H14 -> 942131.24 | I36: =I34*I8+I35*I14 -> 999826.37 | J36: =J34*J8+J35*J14 -> 1059775 | K36: =K34*K8+K35*K14 -> 1120238.3
A38: Tax
A39: Effective tax rate | B39: ='Income Statement'!B19/'Income Statement'!B18 -> 0.19658744 | C39: ='Income Statement'!C19/'Income Statement'!C18 -> 0.23903732 | D39: ='Income Statement'!D19/'Income Statement'!D18 -> 0.2417572 | E39: ='Income Statement'!E19/'Income Statement'!E18 -> 0.23684852 | F39: ='Income Statement'!F19/'Income Statement'!F18 -> 0.23575692 | G39: 0.235 | H39: 0.235 | I39: 0.235 | J39: 0.235 | K39: 0.235
A41: Other
A42: Share buybacks ($K) | B42: =-'Cash Flow'!B34 -> 466462 | C42: =-'Cash Flow'!C34 -> 830140 | D42: =-'Cash Flow'!D34 -> 592349 | E42: =-'Cash Flow'!E34 -> 1001559 | F42: =-'Cash Flow'!F34 -> 2425516 | G42: 1500000 | H42: 1700000 | I42: 1900000 | J42: 1900000 | K42: 1900000
A43: Stock based compensation ($K) | B43: ='Cash Flow'!B11 -> 176392 | C43: ='Cash Flow'!C11 -> 98030 | D43: ='Cash Flow'!D11 -> 124016 | E43: ='Cash Flow'!E11 -> 131730 | F43: ='Cash Flow'!F11 -> 119543 | G43: 150000 | H43: 150000 | I43: 150000 | J43: 150000 | K43: 150000
A44: Diluted shares outstanding (thousands) | B44: 1425550 | C44: 1403100 | D44: 1385500 | E44: 1376555 | F44: 1342616 | G44: 1309000 | H44: 1275000 | I44: 1241000 | J44: 1207000 | K44: 1173000
A50: Scenario Reference Table | B50: Driver | C50: Bear | D50: Base | E50: Bull
B51: Openings 2026E | C51: 280 | D51: 320 | E51: 360
B52: Openings 2027E | C52: 290 | D52: 335 | E52: 385
...

Sheet Scenarios
A1: Chipotle DCF - Scenario Analysis
A3: Metric | B3: Bear | C3: Base | D3: Bull
A4: Average opeings/year | B4: 300 | C4: 350 | D4: 410
A5: AUV growth | B5: 0.011 | C5: 0.023 | D5: 0.04
A6: Food/Bev % | B6: 0.305 | C6: 0.295 | D6: 0.285
A7: Labor % | B7: 0.26 | C7: 0.25 | D7: 0.24
A8: Beta | B8: 1.2 | C8: 1.05 | D8: 0.9
A9: Terminal growth | B9: 0.02 | C9: 0.025 | D9: 0.03
A11: Implied share prices | B11: 13.1 | C11: 19.43 | D11: 29.8
A12: Current price | B12: 32.89 | C12: 32.89 | D12: 32.89
A13: Upside/(downside) | B13: =B11/B12-1 -> -0.60170265 | C13: =C11/C12-1 -> -0.40924293 | D13: =D11/D12-1 -> -0.093949529
A15: Sell side reference
A16: Bear (Guggenheim) | B16: 35
A17: Consensus avg | B17: 46
A18: Bull (citi) | B18: 46
A20: Conclusion
A21: All three scenarios imply CMG is fully valued to overvalued at current levels. Even the bull case (aggressive recovery) implies modest downside.

Sheet Income Statement
A1: Chipotle Mexican Grill - Income Statement
A2: ($ in thousands)
A4: Fiscal Year | B4: 2021A | C4: 2022A | D4: 2023A | E4: 2024A | F4: 2025A | G4: 2026E | H4: 2027E | I4: 2028E | J4: 2029E | K4: 2030E
A6: Revenue | B6: 7547061 | C6: 8634652 | D6: 9871649 | E6: 11313853 | F6: 11925601 | G6: =Assumptions!G14 -> 13128723 | H6: =Assumptions!H14 -> 14444062 | I6: =Assumptions!I14 -> 15866318 | J6: =Assumptions!J14 -> 17401250 | K6: =Assumptions!K14 -> 18961915
A7: Food, beverages and packaging | B7: 2308631 | C7: 2602245 | D7: 2912564 | E7: 3374516 | F7: 3526992 | G7: =Assumptions!G18*G6 -> 3872973.4 | H7: =Assumptions!H18*H6 -> 4260998.3 | I7: =Assumptions!I18*I6 -> 4680563.9 | J7: =Assumptions!J18*J6 -> 5133368.7 | K7: =Assumptions!K18*K6 -> 5593765
A8: Labor | B8: 1917761 | C8: 2197958 | D8: 2440982 | E8: 2789789 | F8: 2991680 | G8: =Assumptions!G19*G6 -> 3282180.9 | H8: =Assumptions!H19*H6 -> 3611015.5 | I8: =Assumptions!I19*I6 -> 3966579.6 | J8: =Assumptions!J19*J6 -> 4350312.4 | K8: =Assumptions!K19*K6 -> 4740478.8
A9: Occupancy | B9: 416606 | C9: 460425 | D9: 503264 | E9: 563374 | F9: 624898 | G9: =Assumptions!G20*G6 -> 669564.89 | H9: =Assumptions!H20*H6 -> 736647.17 | I9: =Assumptions!I20*I6 -> 809182.23 | J9: =Assumptions!J20*J6 -> 870062.48 | K9: =Assumptions!K20*K6 -> 948095.76
A10: Other operating cost | B10: 1197054 | C10: 1311905 | D10: 1428747 | E10: 1568482 | F10: 1755824 | G10: =Assumptions!G21*G6 -> 1903664.9 | H10: =Assumptions!H21*H6 -> 2094389 | I10: =Assumptions!I21*I6 -> 2300616.2 | J10: =Assumptions!J21*J6 -> 2523181.2 | K10: =Assumptions!K21*K6 -> 2749477.7
A11: General and administrative | B11: 606854 | C11: 564191 | D11: 633584 | E11: 697483 | F11: 652017 | G11: =Assumptions!G22*G6 -> 722079.79 | H11: =Assumptions!H22*H6 -> 794423.42 | I11: =Assumptions!I22*I6 -> 872647.51 | J11: =Assumptions!J22*J6 -> 957068.73 | K11: =Assumptions!K22*K6 -> 1042905.3
A12: Depreciation and amortization | B12: 254657 | C12: 286826 | D12: 319394 | E12: 335030 | F12: 361382 | G12: =Assumptions!G23*G6 -> 393861.7 | H12: =Assumptions!H23*H6 -> 433321.86 | I12: =Assumptions!I23*I6 -> 475989.55 | J12: =Assumptions!J23*J6 -> 522037.49 | K12: =Assumptions!K23*K6 -> 568857.46
A13: Pre-opening cost | B13: 21264 | C13: 29560 | D13: 36931 | E13: 41897 | F13: 49507 | G13: =Assumptions!G24*Assumptions!G8 -> 51200 | H13: =Assumptions!H24*Assumptions!H8 -> 53600 | I13: =Assumptions!I24*Assumptions!I8 -> 56000 | J13: =Assumptions!J24*Assumptions!J8 -> 58400 | K13: =Assumptions!K24*Assumptions!K8 -> 60800
A14: Impairment, closure cost | B14: 19291 | C14: 21139 | D14: 38370 | E14: 26949 | F14: 27503 | G14: =Assumptions!G25 -> 30000 | H14: =Assumptions!H25 -> 30000 | I14: =Assumptions!I25 -> 30000 | J14: =Assumptions!J25 -> 30000 | K14: =Assumptions!K25 -> 30000
A15: Total operating expense | B15: =SUM(B7:B14) -> 6742118 | C15: =SUM(C7:C14) -> 7474249 | D15: =SUM(D7:D14) -> 8313836 | E15: =SUM(E7:E14) -> 9397520 | F15: =SUM(F7:F14) -> 9989803 | G15: =SUM(G7:G14) -> 10925526 | H15: =SUM(H7:H14) -> 12014395 | I15: =SUM(I7:I14) -> 13191579 | ... K15: =SUM(K7:K14) -> 15734380
A16: Operating income | B16: =B6-B15 -> 804943 | C16: =C6-C15 -> 1160403 | D16: =D6-D15 -> 1557813 | E16: =E6-E15 -> 1916333 | F16: =F6-F15 -> 1935798 | G16: =G6-G15 -> 2203197.9 | H16: =H6-H15 -> 2429666.8 | I16: =I6-I15 -> 2674739.4 | ... K16: =K6-K15 -> 3227535.2
A17: Interest and other income, net | B17: 7820 | C17: 21128 | D17: 62693 | E17: 93897 | F17: 73721 | G17: 75000 | H17: 75000 | I17: 75000 | J17: 75000 | K17: 75000
A18: Income before taxes | B18: =B16+B17 -> 812763 | C18: =C16+C17 -> 1181531 | D18: =D16+D17 -> 1620506 | E18: =E16+E17 -> 2010230 | F18: =F16+F17 -> 2009519 | G18: =G16+G17 -> 2278197.9 | H18: =H16+H17 -> 2504666.8 | I18: =I16+I17 -> 2749739.4 | ... K18: =K16+K17 -> 3302535.2
A19: Provision for taxes | B19: 159779 | C19: 282430 | D19: 391769 | E19: 476120 | F19: 473758 | G19: =Assumptions!G39*G18 -> 535376.5 | H19: =Assumptions!H39*H18 -> 588596.7 | I19: =Assumptions!I39*I18 -> 646188.75 | J19: =Assumptions!J39*J18 -> 712477.39 | K19: =Assumptions!K39*K18 -> 776095.77
A20: Net Income | B20: =B18-B19 -> 652984 | C20: =C18-C19 -> 899101 | D20: =D18-D19 -> 1228737 | E20: =E18-E19 -> 1534110 | F20: =F18-F19 -> 1535761 | G20: =G18-G19 -> 1742821.4 | H20: =H18-H19 -> 1916070.1 | I20: =I18-I19 -> 2103550.6 | ... K20: =K18-K19 -> 2526439.4

Sheet Balance Sheet
A1: Chipotle Mexican Grill - Balance Sheet
A2: ($ in thousands)
A4: Fiscal Year | B4: 2021A | C4: 2022A | D4: 2023A | E4: 2024A | F4: 2025A | G4: 2026E | H4: 2027E | I4: 2028E | J4: 2029E | K4: 2030E
A6: Cash and equivalents | B6: ='Cash Flow'!B42 - B15 -> 815374 | C6: 384000 | D6: 560609 | E6: 748537 | F6: 350545 | G6: ='Cash Flow'!G42-'Balance Sheet'!G15 -> 163987.32 | H6: ='Cash Flow'!H42-'Balance Sheet'!H15 -> 100186.78 | I6: ='Cash Flow'!I42-'Balance Sheet'!I15 -> 12817.313 | J6: ='Cash Flow'!J42-'Balance Sheet'!J15 -> 131530.05 | K6: ='Cash Flow'!K42-'Balance Sheet'!K15 -> 444655.03
A7: Short-term investments | B7: 260945 | C7: 515136 | D7: 734838 | E7: 674378 | F7: 698591 | G7: =F7 -> 698591 | H7: =G7 -> 698591 | I7: =H7 -> 698591 | J7: =I7 -> 698591 | K7: =J7 -> 698591
A8: Accounts receivable | B8: 99599 | C8: 106880 | D8: 115535 | E8: 143963 | F8: 156466 | G8: =Assumptions!G28/365*'Income Statement'!G6 -> 179845.53 | H8: =Assumptions!H28/365*'Income Statement'!H6 -> 197863.86 | I8: =Assumptions!I28/365*'Income Statement'!I6 -> 217346.83 | J8: =Assumptions!J28/365*'Income Statement'!J6 -> 238373.28 | K8: =Assumptions!K28/365*'Income Statement'!K6 -> 259752.26
A9: Inventory | B9: 32826 | C9: 35668 | D9: 39309 | E9: 48942 | F9: 49508 | G9: =Assumptions!G29/365*'Income Statement'!G7 -> 53054.43 | H9: =Assumptions!H29/365*'Income Statement'!H7 -> 58369.84 | I9: =Assumptions!I29/365*'Income Statement'!I7 -> 64117.314 | J9: =Assumptions!J29/365*'Income Statement'!J7 -> 70320.119 | K9: =Assumptions!K29/365*'Income Statement'!K7 -> 76626.918
A10: Income tax receivable | B10: 94064 | C10: 47741 | D10: 52960 | E10: 67229 | F10: 91393 | G10: =F10 -> 91393 | H10: =G10 -> 91393 | I10: =H10 -> 91393 | J10: =I10 -> 91393 | K10: =J10 -> 91393
A11: Prepaid expenses and other current assets | B11: 78756 | C11: 86412 | D11: 117462 | E11: 97538 | F11: 120450 | G11: =Assumptions!G31*'Income Statement'!G6 -> 262574.47 | H11: =Assumptions!H31*'Income Statement'!H6 -> 288881.24 | I11: =Assumptions!I31*'Income Statement'!I6 -> 317326.37 | J11: =Assumptions!J31*'Income Statement'!J6 -> 348024.99 | K11: =Assumptions!K31*'Income Statement'!K6 -> 379238.31
A12: Total current assets | B12: =sum(B6:B11) -> 1381564 | C12: =sum(C6:C11) -> 1175837 | D12: =sum(D6:D11) -> 1620713 | E12: =sum(E6:E11) -> 1780587 | F12: =sum(F6:F11) -> 1466953 | G12: =SUM(G6:G11) -> 1449445.7 | H12: =SUM(H6:H11) -> 1435285.7 | I12: =SUM(I6:I11) -> 1401591.8 | J12: =SUM(J6:J11) -> 1578232.4 | K12: =SUM(K6:K11) -> 1950256.5
A13: Leasehold improvements, property and equipment, net | B13: 1769278 | C13: 1951147 | D13: 2170038 | E13: 2390126 | F13: 2679361 | G13: =F13+Assumptions!G36-'Income Statement'!G12-'Income Statement'!G14 -> 3142073.8 | H13: =G13+Assumptions!H36-'Income Statement'!H12-'Income Statement'!H14 -> 3620883.1 | I13: =H13+Assumptions!I36-'Income Statement'!I12-'Income Statement'!I14 -> 4114720 | J13: =I13+Assumptions!J36-'Income Statement'!J12-'Income Statement'!J14 -> 4622457.5 | K13: =J13+Assumptions!K36-'Income Statement'!K12-'Income Statement'!K14 -> 5143838.3
A14: Long-term investments | B14: 274311 | C14: 388055 | D14: 564488 | E14: 868025 | F14: 197123 | G14: =F14 -> 197123 | H14: =G14 -> 197123 | I14: =H14 -> 197123 | J14: =I14 -> 197123 | K14: =J14 -> 197123
A15: restricted cash | B15: 30856 | C15: 24966 | D15: 25554 | E15: 29842 | F15: 35364 | G15: =F15 -> 35364 | H15: =G15 -> 35364 | I15: =H15 -> 35364 | J15: =I15 -> 35364 | K15: =J15 -> 35364
A16: Operating lease assets | B16: 3118294 | C16: 3302402 | D16: 3578548 | E16: 4000127 | F16: 4463010 | G16: =F16+('Balance Sheet'!G25-'Balance Sheet'!F25)+('Balance Sheet'!G27-'Balance Sheet'!F27) -> 4975087 | H16: =G16+('Balance Sheet'!H25-'Balance Sheet'!G25)+('Balance Sheet'!H27-'Balance Sheet'!G27) -> 5534925.8 | I16: =H16+('Balance Sheet'!I25-'Balance Sheet'!H25)+('Balance Sheet'!I27-'Balance Sheet'!H27) -> 6140271.2 | J16: =I16+('Balance Sheet'!J25-'Balance Sheet'!I25)+('Balance Sheet'!J27-'Balance Sheet'!I27) -> 6793573.8 | K16: =J16+('Balance Sheet'!K25-'Balance Sheet'!J25)+('Balance Sheet'!K27-'Balance Sheet'!J27) -> 7457829.5
A17: Other long-term assets | B17: 56716 | C17: 63158 | D17: 63082 | E17: 113728 | F17: 130781 | G17: =F17 -> 130781 | H17: =G17 -> 130781 | I17: =H17 -> 130781 | J17: =I17 -> 130781 | K17: =J17 -> 130781
A18: Goodwill | B18: 21939 | C18: 21939 | D18: 21939 | E18: 21939 | F18: 21939 | G18: =F18 -> 21939 | H18: =G18 -> 21939 | I18: =H18 -> 21939 | J18: =I18 -> 21939 | K18: =J18 -> 21939
A19: Total assets | B19: =B12+SUM(B13:B18) -> 6652958 | C19: =C12+SUM(C13:C18) -> 6927504 | D19: =D12+SUM(D13:D18) -> 8044362 | E19: =E12+SUM(E13:E18) -> 9204374 | F19: =F12+SUM(F13:F18) -> 8994531 | G19: =G12+SUM(G13:G18) -> 9951813.5 | H19: =H12+SUM(H13:H18) -> 10976302 | I19: =I12+SUM(I13:I18) -> 12041790 | ... K19: =K12+SUM(K13:K18) -> 14937131
A21: Accounts payable | B21: 163161 | C21: 184566 | D21: 197646 | E21: 210695 | F21: 212813 | G21: =Assumptions!G30/365*'Income Statement'!G7 -> 244050.38 | H21: =Assumptions!H30/365*'Income Statement'!H7 -> 268501.26 | I21: =Assumptions!I30/365*'Income Statement'!I7 -> 294939.64 | J21: =Assumptions!J30/365*'Income Statement'!J7 -> 323472.55 | K21: =Assumptions!K30/365*'Income Statement'!K7 -> 352483.82
A22: Accrued payroll and benefits | B22: 162405 | C22: 170456 | D22: 227537 | E22: 261913 | F22: 250126 | G22: =F22/'Income Statement'!F8*'Income Statement'!G8 -> 274413.96 | H22: =G22/'Income Statement'!G8*'Income Statement'!H8 -> 301906.91 | I22: =H22/'Income Statement'!H8*'Income Statement'!I8 -> 331634.63 | J22: =I22/'Income Statement'!I8*'Income Statement'!J8 -> 363717.46 | K22: =J22/'Income Statement'!J8*'Income Statement'!K8 -> 396338.18
A23: Accrued liabilities | B23: 173052 | C23: 147539 | D23: 147688 | E23: 179747 | F23: 182448 | G23: =F23/'Income Statement'!F6*'Income Statement'!G6 -> 200854.39 | H23: =G23/'Income Statement'!G6*'Income Statement'!H6 -> 220977.56 | I23: =H23/'Income Statement'!H6*'Income Statement'!I6 -> 242736.45 | J23: =I23/'Income Statement'!I6*'Income Statement'!J6 -> 266219.14 | K23: =J23/'Income Statement'!J6*'Income Statement'!K6 -> 290095.53
A24: Unearned revenue | B24: 156351 | C24: 183071 | D24: 209680 | E24: 238577 | F24: 240375 | G24: =F24/'Income Statement'!F6*'Income Statement'!G6 -> 264625.4 | H24: =G24/'Income Statement'!G6*'Income Statement'!H6 -> 291137.65 | I24: =H24/'Income Statement'!H6*'Income Statement'!I6 -> 319804.95 | J24: =I24/'Income Statement'!I6*'Income Statement'!J6 -> 350743.36 | K24: =J24/'Income Statement'!J6*'Income Statement'!K6 -> 382200.48
A25: Current operating lease liabilities | B25: 218713 | C25: 236248 | D25: 248074 | E25: 277836 | F25: 302380 | G25: =F25/'Income Statement'!F6*'Income Statement'!G6 -> 332885.81 | H25: =G25/'Income Statement'!G6*'Income Statement'!H6 -> 366236.93 | I25: =H25/'Income Statement'!H6*'Income Statement'!I6 -> 402299 | J25: =I25/'Income Statement'!I6*'Income Statement'!J6 -> 441218 | K25: =J25/'Income Statement'!J6*'Income Statement'!K6 -> 480789.52
A26: Total current liabilities | B26: =SUM(B21:B25) -> 873682 | C26: =SUM(C21:C25) -> 921880 | D26: =SUM(D21:D25) -> 1030625 | E26: =SUM(E21:E25) -> 1168768 | F26: =SUM(F21:F25) -> 1188142 | G26: =SUM(G21:G25) -> 1316829.9 | H26: =SUM(H21:H25) -> 1448760.3 | I26: =SUM(I21:I25) -> 1591414.7 | ... K26: =SUM(K21:K25) -> 1901907.5
A27: Long-term operating lease liabilities | B27: 3301601 | C27: 3495162 | D27: 3803551 | E27: 4262782 | F27: 4773434 | G27: =F27/'Income Statement'!F6*'Income Statement'!G6 -> 5255005.2 | H27: =G27/'Income Statement'!G6*'Income Statement'!H6 -> 5781492.9 | I27: =H27/'Income Statement'!H6*'Income Statement'!I6 -> 6350776.2 | J27: =I27/'Income Statement'!I6*'Income Statement'!J6 -> 6965159.8 | K27: =J27/'Income Statement'!J6*'Income Statement'!K6 -> 7589844
A28: Deferred income tax liabilities | B28: 141765 | C28: 98623 | D28: 89109 | E28: 46208 | F28: 125674 | G28: =F28 -> 125674 | H28: =G28 -> 125674 | I28: =H28 -> 125674 | J28: =I28 -> 125674 | K28: =J28 -> 125674
A29: Other long-term liabilities | B29: 38536 | C29: 43816 | D29: 58870 | E29: 71070 | F29: 76674 | G29: =F29 -> 76674 | H29: =G29 -> 76674 | I29: =H29 -> 76674 | J29: =I29 -> 76674 | K29: =J29 -> 76674
A30: Total liabilities | B30: =SUM(B26:B29) -> 4355584 | C30: =SUM(C26:C29) -> 4559481 | D30: =SUM(D26:D29) -> 4982155 | E30: =SUM(E26:E29) -> 5548828 | F30: =SUM(F26:F29) -> 6163924 | G30: =G26+SUM(G27:G29) -> 6774183.1 | H30: =H26+SUM(H27:H29) -> 7432601.2 | I30: =I26+SUM(I27:I29) -> 8144538.9 | J30: =J26+SUM(J27:J29) -> 8912878.3 | K30: =K26+SUM(K27:K29) -> 9694099.5
A32: Common stock | B32: 18566 | C32: 18660 | D32: 18741 | E32: 13586 | F32: 13044 | G32: =F32 -> 13044 | H32: =G32 -> 13044 | I32: =H32 -> 13044 | J32: =I32 -> 13044 | K32: =J32 -> 13044
A33: Additional paid-in capital | B33: 1711117 | C33: 1811017 | D33: 1937794 | E33: 2078010 | F33: 2204944 | G33: =F33+Assumptions!G43+'Cash Flow'!G35+'Cash Flow'!G36 -> 2309562 | H33: =G33+Assumptions!H43+'Cash Flow'!H35+'Cash Flow'!H36 -> 2459562 | I33: =H33+Assumptions!I43+'Cash Flow'!I35+'Cash Flow'!I36 -> 2609562 | J33: =I33+Assumptions!J43+'Cash Flow'!J35+'Cash Flow'!J36 -> 2759562 | K33: =J33+Assumptions!K43+'Cash Flow'!K35+'Cash Flow'!K36 -> 2909562
A34: Accumulated other comprehensive loss | B34: -5354 | C34: -7888 | D34: -6657 | E34: -10282 | F34: -7289 | G34: =F34+'Cash Flow'!G39 -> -7705 | H34: =G34+'Cash Flow'!H39 -> -7705 | I34: =H34+'Cash Flow'!I39 -> -7705 | J34: =I34+'Cash Flow'!J39 -> -7705 | K34: =J34+'Cash Flow'!K39 -> -7705
A35: Treasury stock | B35: -3356102 | C35: -4282014 | D35: -4944656 | E35: 0 | F35: 0 | G35: =0 -> 0 | H35: =0 -> 0 | I35: =0 -> 0 | J35: =0 -> 0 | K35: =0 -> 0
A36: Retained earnings | B36: 3929147 | C36: 4828248 | D36: 6056985 | E36: 1574232 | F36: 619908 | G36: =F36+'Income Statement'!G20-Assumptions!G42 -> 862729.38 | H36: =G36+'Income Statement'!H20-Assumptions!H42 -> 1078799.5 | I36: =H36+'Income Statement'!I20-Assumptions!I42 -> 1282350.1 | J36: =I36+'Income Statement'!J20-Assumptions!J42 -> 1701691.4 | K36: =J36+'Income Statement'!K20-Assumptions!K42 -> 2328130.8
A37: Total shareholders' equity | B37: =sum(B32:B36) -> 2297374 | C37: =sum(C32:C36) -> 2368023 | D37: =sum(D32:D36) -> 3062207 | E37: =sum(E32:E36) -> 3655546 | F37: =sum(F32:F36) -> 2830607 | G37: =SUM(G32:G36) -> 3177630.4 | H37: =SUM(H32:H36) -> 3543700.5 | I37: =SUM(I32:I36) -> 3897251.1 | J37: =SUM(J32:J36) -> 4466592.4 | K37: =SUM(K32:K36) -> 5243031.8
A39: Total liabilities + equity | B39: =B30+B37 -> 6652958 | C39: =C30+C37 -> 6927504 | D39: =D30+D37 -> 8044362 | E39: =E30+E37 -> 9204374 | F39: =F30+F37 -> 8994531 | G39: =G30+G37 -> 9951813.5 | H39: =H30+H37 -> 10976302 | I39: =I30+I37 -> 12041790 | ... K39: =K30+K37 -> 14937131
A41: Balance check | B41: =B19-B39 -> 0 | C41: =C19-C39 -> 0 | D41: =D19-D39 -> 0 | E41: =E19-E39 -> 0 | F41: =F19-F39 -> 0 | G41: =G19-G39 -> 1.8626451e-09 | H41: =H19-H39 -> 1.8626451e-09 | I41: =I19-I39 -> 3.7252903e-09 | ... K41: =K19-K39 -> 1.8626451e-09

Sheet Cash Flow
A1: Chipotle Mexican Grill - Cash Flow Statement
A2: ($ in thousands)
A4: Fiscal Year | B4: 2021A | C4: 2022A | D4: 2023A | E4: 2024A | F4: 2025A | G4: 2026E | H4: 2027E | I4: 2028E | J4: 2029E | K4: 2030E
A6: Net income | B6: ='Income Statement'!B20 -> 652984 | C6: ='Income Statement'!C20 -> 899101 | D6: ='Income Statement'!D20 -> 1228737 | E6: ='Income Statement'!E20 -> 1534110 | F6: ='Income Statement'!F20 -> 1535761 | G6: ='Income Statement'!G20 -> 1742821.4 | H6: ='Income Statement'!H20 -> 1916070.1 | I6: ='Income Statement'!I20 -> 2103550.6 | ... K6: ='Income Statement'!K20 -> 2526439.4
A7: Depreciation and amortization | B7: 254657 | C7: 286826 | D7: 319394 | E7: 335030 | F7: 361382 | G7: ='Income Statement'!G12 -> 393861.7 | H7: ='Income Statement'!H12 -> 433321.86 | I7: ='Income Statement'!I12 -> 475989.55 | J7: ='Income Statement'!J12 -> 522037.49 | K7: ='Income Statement'!K12 -> 568857.46
A8: Deferred income tax provision | B8: -12357 | C8: -43195 | D8: -9505 | E8: -42937 | F8: 79483 | G8: 0 | H8: =G8 -> 0 | I8: =H8 -> 0 | J8: =I8 -> 0 | K8: =J8 -> 0
A9: Impairment, closure costs, and asset disposals | B9: 17086 | C9: 20738 | D9: 37025 | E9: 24582 | F9: 26576 | G9: ='Income Statement'!G14 -> 30000 | H9: ='Income Statement'!H14 -> 30000 | I9: ='Income Statement'!I14 -> 30000 | J9: ='Income Statement'!J14 -> 30000 | K9: ='Income Statement'!K14 -> 30000
A10: Provision for credit losses | B10: 493 | C10: -760 | D10: 1570 | E10: 215 | F10: -657 | G10: 0 | H10: =G10 -> 0 | I10: =H10 -> 0 | J10: =I10 -> 0 | K10: =J10 -> 0
A11: Stock-based compensation | B11: 176392 | C11: 98030 | D11: 124016 | E11: 131730 | F11: 119543 | G11: =Assumptions!G43 -> 150000 | H11: =Assumptions!H43 -> 150000 | I11: =Assumptions!I43 -> 150000 | J11: =Assumptions!J43 -> 150000 | K11: =Assumptions!K43 -> 150000
A12: Other | B12: -4599 | C12: -16202 | D12: -13080 | E12: -3472 | F12: -14661 | G12: 0 | H12: =G12 -> 0 | I12: =H12 -> 0 | J12: =I12 -> 0 | K12: =J12 -> 0
A14: Change in accounts receivable | B14: -1687 | C14: -14026 | D14: -11216 | E14: -29274 | F14: -11383 | G14: =-('Balance Sheet'!G8-'Balance Sheet'!F8) -> -23379.526 | H14: =-('Balance Sheet'!H8-'Balance Sheet'!G8) -> -18018.338 | I14: =-('Balance Sheet'!I8-'Balance Sheet'!H8) -> -19482.961 | J14: =-('Balance Sheet'!J8-'Balance Sheet'!I8) -> -21026.457 | K14: =-('Balance Sheet'!K8-'Balance Sheet'!J8) -> -21378.981
A15: Change in inventory | B15: -6392 | C15: -3011 | D15: -3649 | E15: -9797 | F15: -710 | G15: =-('Balance Sheet'!G9-'Balance Sheet'!F9) -> -3546.4303 | H15: =-('Balance Sheet'!H9-'Balance Sheet'!G9) -> -5315.4097 | I15: =-('Balance Sheet'!I9-'Balance Sheet'!H9) -> -5747.4736 | J15: =-('Balance Sheet'!J9-'Balance Sheet'!I9) -> -6202.8049 | K15: =-('Balance Sheet'!K9-'Balance Sheet'!J9) -> -6306.7994
A16: Change in prepaid expenses and other current assets | B16: -26826 | C16: -14660 | D16: -39211 | E16: 9244 | F16: -33042 | G16: =-('Balance Sheet'!G11-'Balance Sheet'!F11) -> -142124.47 | H16: =-('Balance Sheet'!H11-'Balance Sheet'!G11) -> -26306.774 | I16: =-('Balance Sheet'!I11-'Balance Sheet'!H11) -> -28445.124 | J16: =-('Balance Sheet'!J11-'Balance Sheet'!I11) -> -30698.628 | K16: =-('Balance Sheet'!K11-'Balance Sheet'!J11) -> -31213.312
A17: Change in operating lease assets | B17: 223837 | C17: 234273 | D17: 254241 | E17: 285587 | F17: 332685 | G17: =-('Balance Sheet'!G16-'Balance Sheet'!F16) -> -512076.97 | H17: =-('Balance Sheet'!H16-'Balance Sheet'!G16) -> -559838.83 | I17: =-('Balance Sheet'!I16-'Balance Sheet'!H16) -> -605345.41 | J17: =-('Balance Sheet'!J16-'Balance Sheet'!I16) -> -653302.61 | K17: =-('Balance Sheet'!K16-'Balance Sheet'!J16) -> -664255.7
A18: Change in other assets | B18: 3993 | C18: -346 | D18: 4204 | E18: -17690 | F18: -5155 | G18: =-('Balance Sheet'!G17-'Balance Sheet'!F17) -> 0 | H18: =-('Balance Sheet'!H17-'Balance Sheet'!G17) -> 0 | I18: =-('Balance Sheet'!I17-'Balance Sheet'!H17) -> 0 | J18: =-('Balance Sheet'!J17-'Balance Sheet'!I17) -> 0 | K18: =-('Balance Sheet'!K17-'Balance Sheet'!J17) -> 0
A19: Change in accounts payable | B19: 21440 | C19: 18208 | D19: 5313 | E19: 8467 | F19: -7449 | G19: ='Balance Sheet'!G21-'Balance Sheet'!F21 -> 31237.379 | H19: ='Balance Sheet'!H21-'Balance Sheet'!G21 -> 24450.885 | I19: ='Balance Sheet'!I21-'Balance Sheet'!H21 -> 26438.379 | J19: ='Balance Sheet'!J21-'Balance Sheet'!I21 -> 28532.903 | K19: ='Balance Sheet'!K21-'Balance Sheet'!J21 -> 29011.277
A20: Change in payroll and benefits | B20: -44555 | C20: 9864 | D20: 57048 | E20: 34857 | F20: -12113 | G20: ='Balance Sheet'!G22-'Balance Sheet'!F22 -> 24287.964 | H20: ='Balance Sheet'!H22-'Balance Sheet'!G22 -> 27492.947 | I20: ='Balance Sheet'!I22-'Balance Sheet'!H22 -> 29727.716 | J20: ='Balance Sheet'!J22-'Balance Sheet'!I22 -> 32082.83 | K20: ='Balance Sheet'!K22-'Balance Sheet'!J22 -> 32620.722
A21: Change in accrued liabilities | B21: 10997 | C21: -27964 | D21: 3188 | E21: 27284 | F21: -10499 | G21: ='Balance Sheet'!G23-'Balance Sheet'!F23 -> 18406.391 | H21: ='Balance Sheet'!H23-'Balance Sheet'!G23 -> 20123.171 | I21: ='Balance Sheet'!I23-'Balance Sheet'!H23 -> 21758.886 | J21: ='Balance Sheet'!J23-'Balance Sheet'!I23 -> 23482.688 | K21: ='Balance Sheet'!K23-'Balance Sheet'!J23 -> 23876.392
A22: Change in unearned revenue | B22: 34387 | C22: 33374 | D22: 35685 | E22: 46139 | F22: 40710 | G22: ='Balance Sheet'!G24-'Balance Sheet'!F24 -> 24250.396 | H22: ='Balance Sheet'!H24-'Balance Sheet'!G24 -> 26512.252 | I22: ='Balance Sheet'!I24-'Balance Sheet'!H24 -> 28667.304 | J22: ='Balance Sheet'!J24-'Balance Sheet'!I24 -> 30938.41 | K22: ='Balance Sheet'!K24-'Balance Sheet'!J24 -> 31457.115
A23: Change in income tax payable/receivable | B23: 193379 | C23: 46262 | D23: -5237 | E23: -14363 | F23: -24125 | G23: =0 -> 0 | H23: =0 -> 0 | I23: =0 -> 0 | J23: =0 -> 0 | K23: =0 -> 0
A24: Change in operating lease liabilities | B24: -207164 | C24: -207186 | D24: -214477 | E24: -217894 | F24: -258228 | G24: =('Balance Sheet'!G25-'Balance Sheet'!F25)+('Balance Sheet'!G27-'Balance Sheet'!F27) -> 512076.97 | H24: =('Balance Sheet'!H25-'Balance Sheet'!G25)+('Balance Sheet'!H27-'Balance Sheet'!G27) -> 559838.83 | I24: =('Balance Sheet'!I25-'Balance Sheet'!H25)+('Balance Sheet'!I27-'Balance Sheet'!H27) -> 605345.41 | J24: =('Balance Sheet'!J25-'Balance Sheet'!I25)+('Balance Sheet'!J27-'Balance Sheet'!I27) -> 653302.61 | K24: =('Balance Sheet'!K25-'Balance Sheet'!J25)+('Balance Sheet'!K27-'Balance Sheet'!J27) -> 664255.7
A25: Change in other long-term liabilities | B25: -3984 | C25: 3853 | D25: 9431 | E25: 3258 | F25: -4192 | G25: ='Balance Sheet'!G29-'Balance Sheet'!F29 -> 0 | H25: ='Balance Sheet'!H29-'Balance Sheet'!G29 -> 0 | I25: ='Balance Sheet'!I29-'Balance Sheet'!H29 -> 0 | J25: ='Balance Sheet'!J29-'Balance Sheet'!I29 -> 0 | K25: ='Balance Sheet'!K29-'Balance Sheet'!J29 -> 0
A26: Net cash from operating activities | B26: =sum(B6:B25) -> 1282081 | C26: =sum(C6:C25) -> 1323179 | D26: =sum(D6:D25) -> 1783477 | E26: =sum(E6:E25) -> 2105076 | F26: =sum(F6:F25) -> 2113926 | G26: =SUM(G6:G25) -> 2245814.8 | H26: =SUM(H6:H25) -> 2578330.7 | I26: =SUM(I6:I25) -> 2812456.9 | J26: =SUM(J6:J25) -> 3078487.7 | K26: =SUM(K6:K25) -> 3333363.3
A28: Purchase of leasehold improvements, property and equipment | B28: -442475 | C28: -479164 | D28: -560731 | E28: -593603 | F28: -666336 | G28: =-Assumptions!G36 -> -886574.47 | H28: =-Assumptions!H36 -> -942131.24 | I28: =-Assumptions!I36 -> -999826.37 | J28: =-Assumptions!J36 -> -1059775 | K28: =-Assumptions!K36 -> -1120238.3
A29: Purchase of investments | B29: -429350 | C29: -614416 | D29: -1115131 | E29: -986673 | F29: -28222 | G29: 0 | H29: =G29 -> 0 | I29: =H29 -> 0 | J29: =I29 -> 0 | K29: =J29 -> 0
A30: Sales/maturities of investments | B30: 345748 | C30: 263548 | D30: 729853 | E30: 722637 | F30: 659476 | G30: 0 | H30: =G30 -> 0 | I30: =H30 -> 0 | J30: =I30 -> 0 | K30: =J30 -> 0
A31: Proceeds from sale of equipment | B31: 4035 | C31: 0 | D31: 0 | E31: 20113 | F31: 0 | G31: =F31 -> 0 | H31: =G31 -> 0 | I31: =H31 -> 0 | J31: =I31 -> 0 | K31: =J31 -> 0
A32: Net cash from investing activities | B32: =sum(B28:B31) -> -522042 | C32: =sum(C28:C31) -> -830032 | D32: =sum(D28:D31) -> -946009 | E32: =sum(E28:E31) -> -837526 | F32: =sum(F28:F31) -> -35082 | G32: =SUM(G28:G31) -> -886574.47 | H32: =SUM(H28:H31) -> -942131.24 | I32: =SUM(I28:I31) -> -999826.37 | J32: =SUM(J28:J31) -> -1059775 | K32: =SUM(K28:K31) -> -1120238.3
A34: Acquisition of treasury stock | B34: -466462 | C34: -830140 | D34: -592349 | E34: -1001559 | F34: -2425516 | G34: =-Assumptions!G42 -> -1500000 | H34: =-Assumptions!H42 -> -1700000 | I34: =-Assumptions!I42 -> -1900000 | J34: =-Assumptions!J42 -> -1900000 | K34: =-Assumptions!K42 -> -1900000
A35: Tax withholding on stock-based compensation awards | B35: -79870 | C35: -98970 | D35: -69146 | E35: -74229 | F35: -49458 | G35: =F35 -> -49458 | H35: 0 | I35: =H35 -> 0 | J35: =I35 -> 0 | K35: =J35 -> 0
A36: Other financing activities | B36: -2274 | C36: -294 | D36: 843 | E36: 2089 | F36: 4076 | G36: =F36 -> 4076 | H36: 0 | I36: =H36 -> 0 | J36: =I36 -> 0 | K36: =J36 -> 0
A37: Net cash from financing activities | B37: =sum(B34:B36) -> -548606 | C37: =sum(C34:C36) -> -929404 | D37: =sum(D34:D36) -> -660652 | E37: =sum(E34:E36) -> -1073699 | F37: =sum(F34:F36) -> -2470898 | G37: =SUM(G34:G36) -> -1545382 | H37: =SUM(H34:H36) -> -1700000 | I37: =SUM(I34:I36) -> -1900000 | J37: =SUM(J34:J36) -> -1900000 | K37: =SUM(K34:K36) -> -1900000
A39: Effect of exchange rate changes on cash, cash equivalents and restricted cash | B39: -1039 | C39: -1007 | D39: 381 | E39: -1635 | F39: -416 | G39: =F39 -> -416 | H39: 0 | I39: =H39 -> 0 | J39: =I39 -> 0 | K39: =J39 -> 0
A40: Net change in cash, cash equivalents, and restricted cash | B40: =B26+B32+B37+B39 -> 210394 | C40: =C26+C32+C37+C39 -> -437264 | D40: =D26+D32+D37+D39 -> 177197 | E40: =E26+E32+E37+E39 -> 192216 | F40: =F26+F32+F37+F39 -> -392470 | G40: =G26+G32+G37+G39 -> -186557.68 | H40: =H26+H32+H37+H39 -> -63800.539 | I40: =I26+I32+I37+I39 -> -87369.464 | ... K40: =K26+K32+K37+K39 -> 313124.98
A41: Cash, cash equivalents, and restricted cash at beginning of year | B41: 635836 | C41: 846230 | D41: 408966 | E41: 586163 | F41: 778379 | G41: =F42 -> 385909 | H41: =G42 -> 199351.32 | I41: =H42 -> 135550.78 | J41: =I42 -> 48181.313 | K41: =J42 -> 166894.05
A42: Cash, cash equivalents, and restricted cash at end of year | B42: =B40+B41 -> 846230 | C42: =C40+C41 -> 408966 | D42: =D40+D41 -> 586163 | E42: =E40+E41 -> 778379 | F42: =F40+F41 -> 385909 | G42: =G40+G41 -> 199351.32 | H42: =H40+H41 -> 135550.78 | I42: =I40+I41 -> 48181.313 | ... K42: =K40+K41 -> 480019.03
A46: Supplemental disclosure of cash flow information
A47: Income taxes paid | B47: -17831 | C47: 275796 | D47: 400229 | E47: 532862 | F47: 423481
A48: Purchase of leasehold improvements, property and equipment accrued in accounts payable | B48: 63802 | C48: 72021 | D48: 76415 | E48: 82636 | F48: 89429
A49: Repurchase of common stock accrued in accounts payable | B49: 7695 | C49: 4497 | D49: 5643 | E49: 7279 | F49: 22958

Sheet DCF
A1: Chipotle Mexican Grill - DCF Valuation
A2: ($ in thousands except per-share values)
A4: Driver | B4: 2026E | C4: 2027E | D4: 2028E | E4: 2029E | F4: 2030E | G4: Terminal
A6: Unlevered free cash flow build
A7: Operating income (EBIT) | B7: ='Income Statement'!G16 -> 2203197.9 | C7: ='Income Statement'!H16 -> 2429666.8 | D7: ='Income Statement'!I16 -> 2674739.4 | E7: ='Income Statement'!J16 -> 2956818.7 | F7: ='Income Statement'!K16 -> 3227535.2
A8: Effective tax rate | B8: =Assumptions!G39 -> 0.235 | C8: =Assumptions!H39 -> 0.235 | D8: =Assumptions!I39 -> 0.235 | E8: =Assumptions!J39 -> 0.235 | F8: =Assumptions!K39 -> 0.235
A9: NOPAT (EBIT * (1 - tax rate)) | B9: =B7*(1-B8) -> 1685446.4 | C9: =C7*(1-C8) -> 1858695.1 | D9: =D7*(1-D8) -> 2046175.6 | E9: =E7*(1-E8) -> 2261966.3 | F9: =F7*(1-F8) -> 2469064.4
A10: (+) Depreciation and amortization | B10: ='Income Statement'!G12 -> 393861.7 | C10: ='Income Statement'!H12 -> 433321.86 | D10: ='Income Statement'!I12 -> 475989.55 | E10: ='Income Statement'!J12 -> 522037.49 | F10: ='Income Statement'!K12 -> 568857.46
A11: (-) CapEX | B11: =-Assumptions!G36 -> -886574.47 | C11: =-Assumptions!H36 -> -942131.24 | D11: =-Assumptions!I36 -> -999826.37 | E11: =-Assumptions!J36 -> -1059775 | F11: =-Assumptions!K36 -> -1120238.3
A12: (-) Change in net working capital | B12: =-(('Balance Sheet'!G8+'Balance Sheet'!G9+'Balance Sheet'!G11) - ('Balance Sheet'!G21+'Balance Sheet'!G22+'Balance Sheet'!G23+'Balance Sheet'!G24)) + (('Balance Sheet'!F8+'Balance Sheet'!F9+'Balance Sheet'!F11) - ('Balance Sheet'!F21+'Balance Sheet'!F22+'Balance Sheet'!F23+'Balance Sheet'!F24)) -> -70868.294 | C12: =-(('Balance Sheet'!H8+'Balance Sheet'!H9+'Balance Sheet'!H11) - ('Balance Sheet'!H21+'Balance Sheet'!H22+'Balance Sheet'!H23+'Balance Sheet'!H24)) + (('Balance Sheet'!G8+'Balance Sheet'!G9+'Balance Sheet'!G11) - ('Balance Sheet'!G21+'Balance Sheet'!G22+'Balance Sheet'!G23+'Balance Sheet'!G24)) -> 48938.734 | D12: =-(('Balance Sheet'!I8+'Balance Sheet'!I9+'Balance Sheet'!I11) - ('Balance Sheet'!I21+'Balance Sheet'!I22+'Balance Sheet'!I23+'Balance Sheet'!I24)) + (('Balance Sheet'!H8+'Balance Sheet'!H9+'Balance Sheet'!H11) - ('Balance Sheet'!H21+'Balance Sheet'!H22+'Balance Sheet'!H23+'Balance Sheet'!H24)) -> 52916.726 | E12: =-(('Balance Sheet'!J8+'Balance Sheet'!J9+'Balance Sheet'!J11) - ('Balance Sheet'!J21+'Balance Sheet'!J22+'Balance Sheet'!J23+'Balance Sheet'!J24)) + (('Balance Sheet'!I8+'Balance Sheet'!I9+'Balance Sheet'!I11) - ('Balance Sheet'!I21+'Balance Sheet'!I22+'Balance Sheet'!I23+'Balance Sheet'!I24)) -> 57108.94 | F12: =-(('Balance Sheet'!K8+'Balance Sheet'!K9+'Balance Sheet'!K11) - ('Balance Sheet'!K21+'Balance Sheet'!K22+'Balance Sheet'!K23+'Balance Sheet'!K24)) + (('Balance Sheet'!J8+'Balance Sheet'!J9+'Balance Sheet'!J11) - ('Balance Sheet'!J21+'Balance Sheet'!J22+'Balance Sheet'!J23+'Balance Sheet'!J24)) -> 58066.413
A13: Unlevered free cash flow | B13: =B9+B10+B11+B12 -> 1121865.3 | C13: =C9+C10+C11+C12 -> 1398824.5 | D13: =D9+D10+D11+D12 -> 1575255.5 | E13: =E9+E10+E11+E12 -> 1781337.7 | F13: =F9+F10+F11+F12 -> 1975750
A16: WACC calculation
A17: Risk-free rate | B17: 0.042
A18: Equity risk premium | B18: 0.055
A19: Beta | B19: =IF(Assumptions!$N$4="Bear",Assumptions!C64,IF(Assumptions!$N$4="Base",Assumptions!D64,Assumptions!E64)) -> 1.05
A20: Cost of equity | B20: =B17+B19*B18 -> 0.09975
A21: After-tax cost of debt | B21: 0.035
A22: Target equity weight | B22: 0.95
A23: Target debt weight | B23: 0.05
A24: WACC | B24: =B20*B22+B21*B23 -> 0.0965125
A27: Terminal Value
A28: Terminal growth rate (g) | B28: =IF(Assumptions!$N$4="Bear",Assumptions!C65,IF(Assumptions!$N$4="Base",Assumptions!D65,Assumptions!E65)) -> 0.025
A29: 2030 UFCF | B29: =F13 -> 1975750
A30: Terminal value | B30: =B29*(1+B28)/(B24-B28) -> 28318738
A32: Discounting
A33: Discount period | B33: 0.5 | C33: 1.5 | D33: 2.5 | E33: 3.5 | F33: 4.5 | G33: 4.5
A34: Discount factor | B34: =1/(1+$B$24)^B33 -> 0.95497765 | C34: =1/(1+$B$24)^C33 -> 0.87092272 | D34: =1/(1+$B$24)^D33 -> 0.79426611 | E34: =1/(1+$B$24)^E33 -> 0.72435664 | F34: =1/(1+$B$24)^F33 -> 0.66060044 | G34: =1/(1+$B$24)^G33 -> 0.66060044
A35: PV of UFCF | B35: =B13*B34 -> 1071356.3 | C35: =C13*C34 -> 1218268 | D35: =D13*D34 -> 1251172.1 | E35: =E13*E34 -> 1290323.8 | F35: =F13*F34 -> 1305181.3
A36: PV of terminal value | G36: =B30*G34 -> 18707371
A37: Enterprise value | B37: =SUM(B35:F35)+G36 -> 24843672
A38: (-) net debt | B38: =0-'Balance Sheet'!F6-'Balance Sheet'!F7-'Balance Sheet'!F14 -> -1246259
A39: Equity value | B39: =B37-B38 -> 26089931
A40: Diluted share outstanding | B40: =Assumptions!F44 -> 1342616
A41: Implied share price | B41: =B39/B40 -> 19.432162
A42: Current share price | B42: 32.89
A43: Implied upside / (downside) | B43: =B41/B42-1 -> -0.40917721
A45: Recommendation: Sell / Underperform
